Workbook

Sheet Summary
A1: Water Regime — New Target Accounts, Pakistan
A2: New industrial accounts with a clear water or wastewater need, identified by Business Development across 19 core industrial sectors. None appear in Water Regime's existing industry lists, visit plans or project pipeline.
A3: Prepared 08 Oct 2026 · Revised
A5: By priority | B5: Count | D5: By sector | E5: Count | F5: New
A6: Priority 1 — pursue first | B6: =COUNTIF('New Target Accounts'!$K$2:$K$300,1) -> 66 | D6: Textile | E6: =COUNTIF('New Target Accounts'!$D$2:$D$300,D6) -> 52 | F6: =COUNTIFS('New Target Accounts'!$D$2:$D$300,D6,'New Target Accounts'!$P$2:$P$300,"Added 08-Oct-2026") -> 29
A7: Priority 2 — strong prospects | B7: =COUNTIF('New Target Accounts'!$K$2:$K$300,2) -> 224 | D7: Food & Beverage | E7: =COUNTIF('New Target Accounts'!$D$2:$D$300,D7) -> 37 | F7: =COUNTIFS('New Target Accounts'!$D$2:$D$300,D7,'New Target Accounts'!$P$2:$P$300,"Added 08-Oct-2026") -> 7
A8: Priority 3 — longer-term | B8: =COUNTIF('New Target Accounts'!$K$2:$K$300,3) -> 9 | D8: Pharmaceutical & Healthcare | E8: =COUNTIF('New Target Accounts'!$D$2:$D$300,D8) -> 36 | F8: =COUNTIFS('New Target Accounts'!$D$2:$D$300,D8,'New Target Accounts'!$P$2:$P$300,"Added 08-Oct-2026") -> 10
A9: TOTAL | B9: =SUM(B6:B8) -> 299 | D9: Sugar & Distillery | E9: =COUNTIF('New Target Accounts'!$D$2:$D$300,D9) -> 29 | F9: =COUNTIFS('New Target Accounts'!$D$2:$D$300,D9,'New Target Accounts'!$P$2:$P$300,"Added 08-Oct-2026") -> 11
D10: Power | E10: =COUNTIF('New Target Accounts'!$D$2:$D$300,D10) -> 24 | F10: =COUNTIFS('New Target Accounts'!$D$2:$D$300,D10,'New Target Accounts'!$P$2:$P$300,"Added 08-Oct-2026") -> 1
A11: Basis of selection | B11: Count | D11: Chemicals & Petrochemical | E11: =COUNTIF('New Target Accounts'!$D$2:$D$300,D11) -> 20 | F11: =COUNTIFS('New Target Accounts'!$D$2:$D$300,D11,'New Target Accounts'!$P$2:$P$300,"Added 08-Oct-2026") -> 6
A12: Live project signal (EIA filed / new plant announced) | B12: =COUNTIF('New Target Accounts'!$L$2:$L$300,"Live project signal") -> 28 | D12: Automotive | E12: =COUNTIF('New Target Accounts'!$D$2:$D$300,D12) -> 15 | F12: =COUNTIFS('New Target Accounts'!$D$2:$D$300,D12,'New Target Accounts'!$P$2:$P$300,"Added 08-Oct-2026") -> 4
A13: Established operator — PSX-listed, export factory or national brand | B13: =COUNTIF('New Target Accounts'!$L$2:$L$300,"Established operator") -> 271 | D13: Cement | E13: =COUNTIF('New Target Accounts'!$D$2:$D$300,D13) -> 13 | F13: =COUNTIFS('New Target Accounts'!$D$2:$D$300,D13,'New Target Accounts'!$P$2:$P$300,"Added 08-Oct-2026") -> 4
A14: TOTAL | B14: =SUM(B12:B13) -> 299 | D14: Steel & Metals | E14: =COUNTIF('New Target Accounts'!$D$2:$D$300,D14) -> 13 | F14: =COUNTIFS('New Target Accounts'!$D$2:$D$300,D14,'New Target Accounts'!$P$2:$P$300,"Added 08-Oct-2026") -> 5
D15: Glass & Ceramics | E15: =COUNTIF('New Target Accounts'!$D$2:$D$300,D15) -> 10 | F15: =COUNTIFS('New Target Accounts'!$D$2:$D$300,D15,'New Target Accounts'!$P$2:$P$300,"Added 08-Oct-2026") -> 5
A16: This revision | B16: Count | D16: Pulp, Paper & Packaging | E16: =COUNTIF('New Target Accounts'!$D$2:$D$300,D16) -> 9 | F16: =COUNTIFS('New Target Accounts'!$D$2:$D$300,D16,'New Target Accounts'!$P$2:$P$300,"Added 08-Oct-2026") -> 2
A17: Retained from previous list | B17: =COUNTIF('New Target Accounts'!$P$2:$P$300,"Original list") -> 213 | D17: Oil & Gas | E17: =COUNTIF('New Target Accounts'!$D$2:$D$300,D17) -> 9 | F17: =COUNTIFS('New Target Accounts'!$D$2:$D$300,D17,'New Target Accounts'!$P$2:$P$300,"Added 08-Oct-2026") -> 0
A18: Newly researched and added | B18: =COUNTIF('New Target Accounts'!$P$2:$P$300,"Added 08-Oct-2026") -> 86 | D18: EPC / Consultant (Partner) | E18: =COUNTIF('New Target Accounts'!$D$2:$D$300,D18) -> 8 | F18: =COUNTIFS('New Target Accounts'!$D$2:$D$300,D18,'New Target Accounts'!$P$2:$P$300,"Added 08-Oct-2026") -> 0
A19: Textile growth (vs. previous list) | B19: =COUNTIF('New Target Accounts'!$D$2:$D$300,"Textile")/COUNTIFS('New Target Accounts'!$D$2:$D$300,"Textile",'New Target Accounts'!$P$2:$P$300,"Original list")-1 -> 1.2608696 | D19: Leather & Tanneries | E19: =COUNTIF('New Target Accounts'!$D$2:$D$300,D19) -> 7 | F19: =COUNTIFS('New Target Accounts'!$D$2:$D$300,D19,'New Target Accounts'!$P$2:$P$300,"Added 08-Oct-2026") -> 2
D20: Electrical & Appliances | E20: =COUNTIF('New Target Accounts'!$D$2:$D$300,D20) -> 5 | F20: =COUNTIFS('New Target Accounts'!$D$2:$D$300,D20,'New Target Accounts'!$P$2:$P$300,"Added 08-Oct-2026") -> 0
A21: Other sheets | B21: Rows | D21: Mining & Minerals | E21: =COUNTIF('New Target Accounts'!$D$2:$D$300,D21) -> 4 | F21: =COUNTIFS('New Target Accounts'!$D$2:$D$300,D21,'New Target Accounts'!$P$2:$P$300,"Added 08-Oct-2026") -> 0
A22: Live project signals (incl. 2 at existing WR accounts) | B22: =COUNTA('Live Project Signals'!A2:A31) -> 30 | D22: Defence & State Manufacturing | E22: =COUNTIF('New Target Accounts'!$D$2:$D$300,D22) -> 4 | F22: =COUNTIFS('New Target Accounts'!$D$2:$D$300,D22,'New Target Accounts'!$P$2:$P$300,"Added 08-Oct-2026") -> 0
A23: WR active pipeline accounts (Tier A) | B23: =COUNTA('WR Active Pipeline'!B2:B34) -> 33 | D23: Batteries | E23: =COUNTIF('New Target Accounts'!$D$2:$D$300,D23) -> 2 | F23: =COUNTIFS('New Target Accounts'!$D$2:$D$300,D23,'New Target Accounts'!$P$2:$P$300,"Added 08-Oct-2026") -> 0
A24: Master companies (WR lists + new targets) | B24: =COUNTA('Master Companies'!B2:B923) -> 922 | D24: Fertilizer | E24: =COUNTIF('New Target Accounts'!$D$2:$D$300,D24) -> 2 | F24: =COUNTIFS('New Target Accounts'!$D$2:$D$300,D24,'New Target Accounts'!$P$2:$P$300,"Added 08-Oct-2026") -> 0
D25: TOTAL | E25: =SUM(E6:E24) -> 299 | F25: =SUM(F6:F24) -> 86
D27: Priority 1 = largest water footprint and strongest fit, or a live project. Priority 2 = strong industrial prospect. Priority 3 = longer-term. Counts are live formulas over the 'New Target Accounts' sheet.

Sheet New Target Accounts
A1: No. | B1: Company | C1: Group | D1: Sector | E1: Sub-sector | F1: City / site | G1: Province | H1: Water / wastewater need | I1: WR solution | J1: Target decision-makers | K1: Priority | L1: Basis of selection | M1: Evidence / size | N1: Recommended first step | O1: Remarks | P1: Added in | Q1: Source
A2: 1 | B2: Honda Atlas Cars (Pakistan) Ltd | C2: Atlas Group | D2: Automotive | E2: OEM Assembly | F2: Lahore | G2: Punjab | H2: Paint-shop effluent | I2: Paint-shop ETP, RO | J2: Plant Engineering Manager; EHS Manager | K2: 1 | L2: Established operator | M2: Established operator — listed or nationally known | N2: Intro meeting | O2: Atlas group (Atlas Honda) already visited | P2: Original list | Q2: Nationally established manufacturer
A3: 2 | B3: Indus Motor Company Ltd (Toyota) | C3: House of Habib | D3: Automotive | E3: OEM Assembly (paint shop) | F3: Karachi (Port Qasim) | G3: Sindh | H3: Paint-shop effluent; strong Japanese-parent environmental standards | I3: Paint-shop ETP, RO process water, recycling | J3: Plant Engineering Manager; EHS Manager | K3: 1 | L3: Established operator | M3: Established operator — listed or nationally known | N3: Intro via EHS | P3: Original list | Q3: Nationally established manufacturer
A4: 3 | B4: Asia Precious Mining Company | D4: Cement | E4: New cement plant | F4: Punjab — site to confirm | G4: Punjab | H4: Greenfield plant — boiler-feed / WHR water and cooling water | I4: Boiler-feed RO / DM, softening | J4: GM Technical; Power Plant Manager | K4: 1 | L4: Live project signal | M4: One of 7 new cement plants approved, US$700M combined (Apr-2026) | N4: Meet project / engineering head while design is open | P4: Added 08-Oct-2026 | Q4: https://e.ccement.com/news/content/67531448976165001.html
A5: 4 | B5: Bestway Cement Ltd | C5: Bestway | D5: Cement | E5: Cement (multi-plant) | F5: Hattar / Chakwal / Kallar Kahar | G5: Punjab | H5: Largest cement group — multiple plants with captive power | I5: Boiler-feed RO/DM, cooling water | J5: GM Technical; Power Plant Manager | K5: 1 | L5: Established operator | M5: Established operator — listed or nationally known | N5: Intro meeting | P5: Original list | Q5: Nationally established manufacturer
A6: 5 | B6: Buta Cement | D6: Cement | E6: New cement plant | F6: Punjab — site to confirm | G6: Punjab | H6: Greenfield plant — boiler-feed / WHR water and cooling water | I6: Boiler-feed RO / DM, softening | J6: GM Technical; Power Plant Manager | K6: 1 | L6: Live project signal | M6: One of 7 new cement plants approved, US$700M combined (Apr-2026) | N6: Meet project / engineering head while design is open | P6: Added 08-Oct-2026 | Q6: https://e.ccement.com/news/content/67531448976165001.html
A7: 6 | B7: Dandot Cement Company Ltd | D7: Cement | E7: Cement (new project) | F7: Dandot (Jhelum) | G7: Punjab | H7: New / revived capacity — boiler-feed and cooling water | I7: Boiler-feed RO / DM, softening | J7: GM Technical; Power Plant Manager | K7: 1 | L7: Live project signal | M7: One of 7 new cement plants approved, US$700M combined (Apr-2026) | N7: Meet project / engineering head while design is open | P7: Added 08-Oct-2026 | Q7: https://e.ccement.com/news/content/67531448976165001.html
A8: 7 | B8: Fauji Cement Company Ltd | C8: Fauji Foundation | D8: Cement | E8: Cement (multi-plant) | F8: Jhang Bahtar / Nizampur / D.G. Khan | G8: Punjab | H8: Multi-plant cement | I8: Boiler-feed RO/DM | J8: GM Technical | K8: 1 | L8: Established operator | M8: Established operator — listed or nationally known | N8: Intro meeting | P8: Original list | Q8: Nationally established manufacturer
A9: 8 | B9: Maple Leaf Cement Factory Ltd | C9: Kohinoor Maple Leaf Group | D9: Cement | E9: Cement | F9: Daudkhel | G9: Punjab | H9: Large plant with captive power | I9: Boiler-feed RO/DM | J9: GM Technical | K9: 1 | L9: Established operator | M9: Established operator — listed or nationally known | N9: Intro meeting | P9: Original list | Q9: Nationally established manufacturer
A10: 9 | B10: Oriental Cement (Pvt) Ltd | D10: Cement | E10: New cement plant | F10: Punjab — site to confirm | G10: Punjab | H10: Greenfield plant — boiler-feed / WHR water and cooling water | I10: Boiler-feed RO / DM, softening | J10: GM Technical; Power Plant Manager | K10: 1 | L10: Live project signal | M10: One of 7 new cement plants approved, US$700M combined (Apr-2026) | N10: Meet project / engineering head while design is open | P10: Added 08-Oct-2026 | Q10: https://e.ccement.com/news/content/67531448976165001.html
A11: 10 | B11: Emcon Chemicals (Pvt) Ltd | D11: Chemicals & Petrochemical | E11: Chemicals (new unit) | F11: Value Addition City, Chak Jhumra (Faisalabad) | G11: Punjab | H11: New chemical unit — process water and chemical effluent treatment | I11: DM / RO, brine treatment, ETP, ZLD | J11: Plant Manager; Engineering Manager; EHS Manager | K11: 1 | L11: Live project signal | M11: Punjab EPD EIA register: new unit at Value Addition City | N11: Meet project / engineering head while design is open | P11: Added 08-Oct-2026 | Q11: https://epd.punjab.gov.pk/eia-reports
A12: 11 | B12: Ittehad Chemicals Ltd | C12: Ittehad | D12: Chemicals & Petrochemical | E12: Chlor-alkali | F12: Kala Shah Kaku | G12: Punjab | H12: Chlor-alkali — brine & effluent | I12: Brine RO, ETP | J12: GM Technical | K12: 1 | L12: Established operator | M12: Established operator — listed or nationally known | N12: Intro meeting | P12: Original list | Q12: Nationally established manufacturer
A13: 12 | B13: Premier Industrial Chemical Manufacturing Co (Pvt) Ltd | D13: Chemicals & Petrochemical | E13: Starch (new unit) | F13: Kot Saleem, Sheikhupura | G13: Punjab | H13: Starch processing — high-COD effluent, anaerobic treatment opportunity | I13: DM / RO, brine treatment, ETP, ZLD | J13: Plant Manager; Engineering Manager; EHS Manager | K13: 1 | L13: Live project signal | M13: Punjab EPD EIA register: construction of starch pack unit | N13: Meet project / engineering head while design is open | P13: Added 08-Oct-2026 | Q13: https://epd.punjab.gov.pk/eia-reports
A14: 13 | B14: Sitara Chemical Industries Ltd | C14: Sitara Group | D14: Chemicals & Petrochemical | E14: Chlor-alkali | F14: Faisalabad | G14: Punjab | H14: Chlor-alkali in Faisalabad — brine & effluent | I14: Brine RO, ETP | J14: GM Technical | K14: 1 | L14: Established operator | M14: Established operator — listed or nationally known | N14: Intro meeting | P14: Original list | Q14: Nationally established manufacturer
A15: 14 | B15: Descon Engineering Ltd | C15: Descon | D15: EPC / Consultant (Partner) | E15: EPC Contractor | F15: Lahore | G15: Punjab | H15: Major EPC — industrial & power projects | I15: Water-package subcontracting | J15: Business Development Head; Project Director; Procurement Manager | K15: 1 | L15: Established operator | M15: Established operator — listed or nationally known | N15: Vendor registration | P15: Original list | Q15: Nationally established manufacturer
A16: 15 | B16: Frontier Works Organization (FWO) | C16: Government | D16: EPC / Consultant (Partner) | E16: Infrastructure Contractor | F16: Rawalpindi | G16: Punjab | H16: Large infrastructure contractor (SEZs, highways, water) | I16: Water-package subcontracting | J16: Business Development Head; Project Director; Procurement Manager | K16: 1 | L16: Established operator | M16: Established operator — listed or nationally known | N16: Vendor registration | P16: Original list | Q16: Nationally established manufacturer
A17: 16 | B17: Habib Rafiq (Pvt) Ltd | C17: Habib Rafiq | D17: EPC / Consultant (Partner) | E17: Construction Contractor | F17: Lahore | G17: Punjab | H17: Major contractor on mega projects (housing, infrastructure) | I17: Water-package subcontracting | J17: Business Development Head; Project Director; Procurement Manager | K17: 1 | L17: Established operator | M17: Established operator — listed or nationally known | N17: Vendor registration | P17: Original list | Q17: Nationally established manufacturer
A18: 17 | B18: NESPAK (National Engineering Services Pakistan) | C18: Government | D18: EPC / Consultant (Partner) | E18: Engineering Consultant | F18: Lahore | G18: Punjab | H18: Lead consultant on public WWTP/water projects — specification influence | I18: Specification support / approved vendor | J18: Business Development Head; Project Director; Procurement Manager | K18: 1 | L18: Established operator | M18: Established operator — listed or nationally known | N18: Technical presentation to water division | P18: Original list | Q18: Nationally established manufacturer
A19: 18 | B19: AA Poultry Protein | D19: Food & Beverage | E19: Poultry rendering (new unit) | F19: Kasur | G19: Punjab | H19: Rendering effluent with very high BOD / fats — DAF + anaerobic / aerobic treatment | I19: RO / UF process water, anaerobic + aerobic ETP, water reuse | J19: Plant Manager; Utilities Manager; EHS Manager | K19: 1 | L19: Live project signal | M19: Punjab EPD EIA register: poultry protein rendering unit | N19: Meet project / engineering head while design is open | P19: Added 08-Oct-2026 | Q19: https://epd.punjab.gov.pk/eia-reports
A20: 19 | B20: Coca-Cola İçecek Pakistan Ltd | C20: Coca-Cola İçecek | D20: Food & Beverage | E20: Carbonated Soft Drinks (multi-plant) | F20: Lahore / Karachi / Faisalabad / Multan / Islamabad | G20: Punjab | H20: Multi-plant bottler; global water-use-ratio targets; process + bottle-wash water | I20: RO/UF process water, ETP, recycling | J20: Plant Manager; Engineering Manager; Utilities Manager; EHS Manager; Procurement Manager | K20: 1 | L20: Live project signal | M20: Sindh EPA EIA: 'Karachi Greenfield' bottling plant, Port Qasim — US$40.5M, ~101,000 bottles/hr | N20: Corporate engineering intro (multi-plant framework) | P20: Original list | Q20: https://epa.sindh.gov.pk/files/EPA-Sindh/EIA-IEE/EIA%20CCI%20Greenfield%20Karachi%20Report.pdf
A21: 20 | B21: FrieslandCampina Engro Pakistan Ltd | C21: FrieslandCampina | D21: Food & Beverage | E21: Dairy | F21: Sahiwal / Sukkur | G21: Punjab | H21: Large dairy processing (high BOD effluent, CIP water) | I21: Anaerobic + aerobic ETP, RO | J21: Plant Manager; Engineering Manager; Utilities Manager; EHS Manager; Procurement Manager | K21: 1 | L21: Established operator | M21: Established operator — listed or nationally known | N21: Intro meeting | P21: Original list | Q21: Nationally established manufacturer
A22: 21 | B22: Haleeb Foods Ltd | C22: Haleeb | D22: Food & Beverage | E22: Dairy | F22: Lahore | G22: Punjab | H22: Dairy processing effluent | I22: Dairy ETP | J22: Plant Manager; Engineering Manager; Utilities Manager; EHS Manager; Procurement Manager | K22: 1 | L22: Established operator | M22: Established operator — listed or nationally known | N22: Intro meeting | P22: Original list | Q22: Nationally established manufacturer
A23: 22 | B23: Nestlé Pakistan Ltd — Sheikhupura Factory | C23: Nestlé | D23: Food & Beverage | E23: Dairy / Beverages / Water | F23: Sheikhupura | G23: Punjab | H23: Multi-plant dairy/water operation; global water-stewardship commitments | I23: Dairy ETP, water reuse, RO | J23: Plant Manager; Engineering Manager; Utilities Manager; EHS Manager; Procurement Manager | K23: 1 | L23: Established operator | M23: Established operator — listed or nationally known | N23: Group engineering intro; water-stewardship angle | P23: Original list | Q23: Nationally established manufacturer
A24: 23 | B24: Ghani Glass Ltd | C24: Ghani Group | D24: Glass & Ceramics | E24: Container / Float Glass | F24: Sheikhupura / Hattar | G24: Punjab | H24: Large glass plants — cooling & process water | I24: Cooling water, softening, RO | J24: Plant Manager | K24: 1 | L24: Established operator | M24: Established operator — listed or nationally known | N24: Intro meeting | P24: Original list | Q24: Nationally established manufacturer
A25: 24 | B25: Hui Huang Sanitary Solutions (Pvt) Ltd | D25: Glass & Ceramics | E25: Sanitary ware & tiles (new plant) | F25: Allama Iqbal Industrial City, Faisalabad | G25: Punjab | H25: Greenfield ceramics plant — slip / glaze wastewater and process-water recycling | I25: Softening, RO, cooling-water treatment | J25: Plant Manager | K25: 1 | L25: Live project signal | M25: Punjab EPD EIA register: establishment of ceramic sanitary-ware and tile plant | N25: Meet project / engineering head while design is open | P25: Added 08-Oct-2026 | Q25: https://epd.punjab.gov.pk/eia-reports
A26: 25 | B26: Kasur Tanneries (Pvt) Ltd | D26: Leather & Tanneries | E26: Tannery | F26: Kasur | G26: Punjab | H26: Chrome-bearing tannery effluent — chrome recovery and ETP | I26: Chrome recovery, CETP, ETP | J26: Plant Manager; Tanners' association | K26: 1 | L26: Live project signal | M26: Punjab EPD EIA 2025 filing | N26: Meet project / engineering head while design is open | P26: Added 08-Oct-2026 | Q26: https://epd.punjab.gov.pk/system/files/2025%20253.pdf
A27: 26 | B27: Korangi Tannery Zone (Sector 7-A) — CETP | C27: Pakistan Tanners Association / KWSC | D27: Leather & Tanneries | E27: Tannery CETP | F27: Karachi | G27: Sindh | H27: Tannery cluster effluent | I27: Chrome recovery + CETP | J27: Project Director; Chief Engineer; Procurement/Tender Cell | K27: 1 | L27: Established operator | M27: Established operator — listed or nationally known | N27: Tanners association meeting | O27: Cluster target — tender route | P27: Original list | Q27: Nationally established manufacturer
A28: 27 | B28: Attock Refinery Ltd | C28: Attock Group | D28: Oil & Gas | E28: Refinery | F28: Rawalpindi | G28: Punjab | H28: Refinery upgrade programme; effluent & process water | I28: Refinery ETP, RO reuse | J28: Plant Manager; Chemistry/Water Treatment Manager; O&M Manager; Procurement Manager | K28: 1 | L28: Established operator | M28: Established operator — listed or nationally known | N28: Use PRL/PARCO references | P28: Original list | Q28: Nationally established manufacturer
A29: 28 | B29: Aga Khan University Hospital | C29: AKDN | D29: Pharmaceutical & Healthcare | E29: Tertiary Hospital (dialysis, CSSD, STP) | F29: Karachi | G29: Sindh | H29: Large tertiary hospital — dialysis water, CSSD, STP | I29: Dialysis-grade RO, STP | J29: Director Facilities; Biomedical Engineering | K29: 1 | L29: Established operator | M29: Established operator — listed or nationally known | N29: Facilities head meeting | P29: Original list | Q29: Nationally established manufacturer
A30: 29 | B30: Arber Pharma | D30: Pharmaceutical & Healthcare | E30: New formulation plant | F30: Sundar Industrial Estate, Lahore | G30: Punjab | H30: Greenfield plant — purified water system and ETP | I30: 2-pass RO + EDI purified water, UF, containerized ETP | J30: Head of Engineering; Utilities Manager; QA / Validation | K30: 1 | L30: Live project signal | M30: Punjab EPD EIA register: construction of pharmaceutical facility | N30: Meet project / engineering head while design is open | P30: Added 08-Oct-2026 | Q30: https://epd.punjab.gov.pk/eia-reports
A31: 30 | B31: Bio Grow Pharmaceuticals (Pvt) Ltd | D31: Pharmaceutical & Healthcare | E31: New formulation plant | F31: Quaid-e-Azam Business Park, Sheikhupura | G31: Punjab | H31: Greenfield plant — purified water system and ETP | I31: 2-pass RO + EDI purified water, UF, containerized ETP | J31: Head of Engineering; Utilities Manager; QA / Validation | K31: 1 | L31: Live project signal | M31: Punjab EPD EIA register: construction of pharmaceutical factory (QABP SEZ) | N31: Meet project / engineering head while design is open | P31: Added 08-Oct-2026 | Q31: https://epd.punjab.gov.pk/eia-reports
A32: 31 | B32: Crystolite Pharmaceuticals | D32: Pharmaceutical & Healthcare | E32: New formulation plant | F32: National Industrial Zone, Rawat (Rawalpindi) | G32: Punjab | H32: Greenfield plant — purified water system and ETP | I32: 2-pass RO + EDI purified water, UF, containerized ETP | J32: Head of Engineering; Utilities Manager; QA / Validation | K32: 1 | L32: Live project signal | M32: Punjab EPD EIA register: construction on plots 70–72-B, NIZ Rawat | N32: Meet project / engineering head while design is open | P32: Added 08-Oct-2026 | Q32: https://epd.punjab.gov.pk/eia-reports
A33: 32 | B33: Gist Pharmaceuticals (Pvt) Ltd | D33: Pharmaceutical & Healthcare | E33: Veterinary pharmaceuticals (new plant) | F33: Sheikhupura–Sharqpur Road | G33: Punjab | H33: Greenfield plant — purified water system and ETP | I33: 2-pass RO + EDI purified water, UF, containerized ETP | J33: Head of Engineering; Utilities Manager; QA / Validation | K33: 1 | L33: Live project signal | M33: Punjab EPD EIA register: establishment of veterinary pharmaceutical facility | N33: Meet project / engineering head while design is open | P33: Added 08-Oct-2026 | Q33: https://epd.punjab.gov.pk/eia-reports
A34: 33 | B34: GSK Pakistan Ltd | C34: GSK | D34: Pharmaceutical & Healthcare | E34: Formulation (orals, sterile) | F34: Karachi | G34: Sindh | H34: Multinational pharma — purified water, WFI, effluent | I34: Purified water (RO/EDI), ETP | J34: Plant Director; Head of Engineering; Utilities Manager; QA/Validation Manager; Procurement Manager | K34: 1 | L34: Established operator | M34: Established operator — listed or nationally known | N34: Intro via engineering head | P34: Original list | Q34: Nationally established manufacturer
A35: 34 | B35: Health Capsules Pakistan (Pvt) Ltd | D35: Pharmaceutical & Healthcare | E35: Capsule shells (new plant) | F35: M-3 Industrial City, Faisalabad | G35: Punjab | H35: Gelatine capsule production — purified process water and effluent treatment | I35: 2-pass RO + EDI purified water, UF, containerized ETP | J35: Head of Engineering; Utilities Manager; QA / Validation | K35: 1 | L35: Live project signal | M35: Punjab EPD EIA register: establishment of capsule-shell manufacturing plant | N35: Meet project / engineering head while design is open | P35: Added 08-Oct-2026 | Q35: https://epd.punjab.gov.pk/eia-reports
A36: 35 | B36: Neutro Pharma (Pvt) Ltd | D36: Pharmaceutical & Healthcare | E36: New formulation plant | F36: Ferozewala, Sheikhupura | G36: Punjab | H36: Greenfield plant — purified water system and ETP | I36: 2-pass RO + EDI purified water, UF, containerized ETP | J36: Head of Engineering; Utilities Manager; QA / Validation | K36: 1 | L36: Live project signal | M36: Punjab EPD EIA register: construction of pharmaceutical unit | N36: Meet project / engineering head while design is open | P36: Added 08-Oct-2026 | Q36: https://epd.punjab.gov.pk/eia-reports
A37: 36 | B37: Pharmagen Ltd | D37: Pharmaceutical & Healthcare | E37: Formulation (extension) | F37: Ferozepur Road, Lahore | G37: Punjab | H37: Plant extension — purified water capacity, boiler-feed water and ETP | I37: 2-pass RO + EDI purified water, UF, containerized ETP | J37: Head of Engineering; Utilities Manager; QA / Validation | K37: 1 | L37: Live project signal | M37: Punjab EPD EIA register: extension of manufacturing unit + biomass boiler | N37: Meet project / engineering head while design is open | P37: Added 08-Oct-2026 | Q37: https://epd.punjab.gov.pk/eia-reports
A38: 37 | B38: Shaukat Khanum Memorial Cancer Hospital — Karachi (project) | C38: SKMCH&RC | D38: Pharmaceutical & Healthcare | E38: Tertiary Hospital (new build) | F38: Karachi | G38: Sindh | H38: New Karachi hospital build — greenfield utilities | I38: WTP + STP package | J38: Director Projects / Facilities | K38: 1 | L38: Live project signal | M38: New hospital build in Karachi (under construction / phased) | N38: Engage project team | O38: Under construction / phased — greenfield signal | P38: Original list | Q38: Nationally established manufacturer
A39: 38 | B39: Sindh Institute of Urology & Transplantation (SIUT) | C39: SIUT | D39: Pharmaceutical & Healthcare | E39: Renal / Dialysis | F39: Karachi | G39: Sindh | H39: Major renal/dialysis centre — ultrapure dialysis water | I39: Dialysis-grade double-pass RO | J39: Biomedical Engineering Head | K39: 1 | L39: Established operator | M39: Established operator — listed or nationally known | N39: Intro meeting | P39: Original list | Q39: Nationally established manufacturer
A40: 39 | B40: Synogen Pharma (Pvt) Ltd | D40: Pharmaceutical & Healthcare | E40: New formulation plant | F40: Quaid-e-Azam Business Park, Sheikhupura | G40: Punjab | H40: Greenfield plant — needs purified water (2-pass RO + EDI), validated loop and effluent treatment | I40: 2-pass RO + EDI purified water, UF, containerized ETP | J40: Head of Engineering; Utilities Manager; QA / Validation | K40: 1 | L40: Live project signal | M40: Punjab EPD EIA register: establishment of pharmaceutical manufacturing unit (QABP SEZ) | N40: Meet project / engineering head while design is open | P40: Added 08-Oct-2026 | Q40: https://epd.punjab.gov.pk/eia-reports
...

Sheet Live Project Signals
A1: Company / project | B1: Sector | C1: Location | D1: What is happening | E1: Water Regime opportunity | F1: List | G1: Source
A2: Asia Precious Mining Company | B2: Cement | C2: Punjab — site to confirm | D2: One of 7 new cement plants approved, US$700M combined (Apr-2026) | E2: Greenfield plant — boiler-feed / WHR water and cooling water | F2: New target | G2: https://e.ccement.com/news/content/67531448976165001.html
A3: Buta Cement | B3: Cement | C3: Punjab — site to confirm | D3: One of 7 new cement plants approved, US$700M combined (Apr-2026) | E3: Greenfield plant — boiler-feed / WHR water and cooling water | F3: New target | G3: https://e.ccement.com/news/content/67531448976165001.html
A4: Dandot Cement Company Ltd | B4: Cement | C4: Dandot (Jhelum) | D4: One of 7 new cement plants approved, US$700M combined (Apr-2026) | E4: New / revived capacity — boiler-feed and cooling water | F4: New target | G4: https://e.ccement.com/news/content/67531448976165001.html
A5: Oriental Cement (Pvt) Ltd | B5: Cement | C5: Punjab — site to confirm | D5: One of 7 new cement plants approved, US$700M combined (Apr-2026) | E5: Greenfield plant — boiler-feed / WHR water and cooling water | F5: New target | G5: https://e.ccement.com/news/content/67531448976165001.html
A6: Emcon Chemicals (Pvt) Ltd | B6: Chemicals & Petrochemical | C6: Value Addition City, Chak Jhumra (Faisalabad) | D6: Punjab EPD EIA register: new unit at Value Addition City | E6: New chemical unit — process water and chemical effluent treatment | F6: New target | G6: https://epd.punjab.gov.pk/eia-reports
A7: Premier Industrial Chemical Manufacturing Co (Pvt) Ltd | B7: Chemicals & Petrochemical | C7: Kot Saleem, Sheikhupura | D7: Punjab EPD EIA register: construction of starch pack unit | E7: Starch processing — high-COD effluent, anaerobic treatment opportunity | F7: New target | G7: https://epd.punjab.gov.pk/eia-reports
A8: AA Poultry Protein | B8: Food & Beverage | C8: Kasur | D8: Punjab EPD EIA register: poultry protein rendering unit | E8: Rendering effluent with very high BOD / fats — DAF + anaerobic / aerobic treatment | F8: New target | G8: https://epd.punjab.gov.pk/eia-reports
A9: Coca-Cola İçecek Pakistan Ltd | B9: Food & Beverage | C9: Lahore / Karachi / Faisalabad / Multan / Islamabad | D9: Sindh EPA EIA: 'Karachi Greenfield' bottling plant, Port Qasim — US$40.5M, ~101,000 bottles/hr | E9: Multi-plant bottler; global water-use-ratio targets; process + bottle-wash water | F9: New target | G9: https://epa.sindh.gov.pk/files/EPA-Sindh/EIA-IEE/EIA%20CCI%20Greenfield%20Karachi%20Report.pdf
A10: Hui Huang Sanitary Solutions (Pvt) Ltd | B10: Glass & Ceramics | C10: Allama Iqbal Industrial City, Faisalabad | D10: Punjab EPD EIA register: establishment of ceramic sanitary-ware and tile plant | E10: Greenfield ceramics plant — slip / glaze wastewater and process-water recycling | F10: New target | G10: https://epd.punjab.gov.pk/eia-reports
A11: Kasur Tanneries (Pvt) Ltd | B11: Leather & Tanneries | C11: Kasur | D11: Punjab EPD EIA 2025 filing | E11: Chrome-bearing tannery effluent — chrome recovery and ETP | F11: New target | G11: https://epd.punjab.gov.pk/system/files/2025%20253.pdf
A12: Arber Pharma | B12: Pharmaceutical & Healthcare | C12: Sundar Industrial Estate, Lahore | D12: Punjab EPD EIA register: construction of pharmaceutical facility | E12: Greenfield plant — purified water system and ETP | F12: New target | G12: https://epd.punjab.gov.pk/eia-reports
... A31: Fauji Fertilizer Company — Thar coal-to-urea project | B31: Fertilizer | C31: Thar coalfield (expected), Sindh | D31: CPEC phase-2 coal-gasification urea plant: ~717,000 t/yr urea, US$1.12bn; FEED signed with Hualu Engineering (May-2026); commissioning 2030–31 | E31: Very large raw-water, demin, cooling and ZLD scope — engage early with FFC and the FEED contractor | F31: Existing WR contact (FFBL, now part of FFC) | G31: https://www.arabnews.com/node/2645462/amp

Sheet WR Active Pipeline
A1: No. | B1: Account | C1: Sector | D1: Tier | E1: WR status | F1: Opportunity (from WR files) | G1: WR solution | H1: Decision-maker titles | I1: Pipeline value PKR | J1: Expected to close PKR (Dec-26) | K1: Next action
A2: 1 | B2: Al-Karam Textile Mills | C2: Textile | D2: A | E2: Existing Customer | F2: Two large ETP proposals in WR pipeline (375 m³/hr MBR + 125 m³/hr MBR); 75% close probability on 125 m³/hr | G2: MBR ETP + recycling | H2: Director Technical; GM Utilities; ETP Manager | I2: 733600000 | J2: 324268000 | K2: Push 125 m³/hr MBR to PO before Dec-26; position 375 m³/hr as phase 2
A3: 2 | B3: Gul Ahmed Textile Mills | C3: Textile | D3: A | E3: Active Opportunity | F3: ETP extension 94→166 m³/hr + BWRO 2×58 + HBWRO 25 m³/hr (PKR 588M) — largest single proposal in pipeline | G3: IFAS/MBR ETP + BWRO recycling | H3: Director Technical; GM Utilities; ETP Manager | I3: 587880000 | K3: Technical clarification meeting; secure commercial negotiation date
A4: 3 | B4: Nishat Mills | C4: Textile | D4: A | E4: Active Opportunity | F4: ETP upgrade 40→80 m³/hr MBR + RO 25 m³/hr (PKR 215M, 75%); group has multiple mills + power + cement | G4: MBR ETP + RO recycling | H4: Director Technical; GM Utilities; Group Sustainability | J4: 214720000 | K4: Close current deal; open group-level framework for other Nishat units
A5: 4 | B5: Feroze1888 Mills | C5: Textile | D5: A | E5: Existing Customer | F5: Five proposals across C-3 and Hub units (ETP 100 m³/hr upgrade, Hub ETP 47.5→95 m³/hr, HBWRO ×2) | G5: DAF + MBBR/MBR hybrid ETP, HBWRO, recycling | H5: Director Technical; GM Utilities; ETP Manager | I5: 635720000 | K5: Consolidate 5 proposals into one programme offer with phased delivery
A6: 5 | B6: Siddiqsons Ltd | C6: Textile | D6: A | E6: Existing Customer | F6: BWRO 2×47.5 m³/hr + ETP 60→120 m³/hr MBR; existing customer | G6: MBR ETP + BWRO | H6: GM Utilities; Director Technical | I6: 245311200 | K6: Follow up on ETP extension; reference-site leverage
A7: 6 | B7: Rajby Industries | C7: Textile | D7: A | E7: Existing Customer | F7: Recycling UF 72 + BWRO 50 m³/hr; multiple units (Washing 1, Unit 3, Kotri denim); existing customer | G7: UF + BWRO recycling, HBWRO, clarifier WTP | H7: GM Utilities; ETP Manager | I7: 233848000 | K7: Convert Kotri budgetary proposals to firm offers
A8: 7 | B8: Artistic Garment Industries (AGI Denim / AGI K-units) | C8: Textile | D8: A | E8: Active Opportunity | F8: ETP extension 80→160 m³/hr + sand classifier 189 m³/hr (75%) | G8: ETP extension, sand classifier | H8: GM Utilities; Manager ETP | I8: 213732000 | J8: 20874000 | K8: Close sand classifier; reopen ETP extension
A9: 8 | B9: Artistic Milliners | C9: Textile | D9: A | E9: Active Opportunity | F9: ETP upgrade to 96 m³/hr MBR + RO 67 m³/hr — 95% probability, technical submission stage | G9: MBR ETP + RO recycling | H9: Director Technical; GM Utilities | K9: Finalise technical approval and price this month
A10: 9 | B10: Nishat Chunian | C10: Textile | D10: A | E10: Active Opportunity | F10: Effluent recycling UF 53.5 + BWRO 37.5 m³/hr (PKR 97M, 50%) | G10: UF + BWRO recycling | H10: GM Utilities; Director Technical | J10: 96853200 | K10: Technical presentation on recovery % and payback
A11: 10 | B11: Fazal Cloth Mills | C11: Textile | D11: A | E11: Active Opportunity | F11: ETP 50 m³/hr (PKR 67M, 75%) | G11: Conventional / MBBR ETP | H11: GM Utilities | J11: 66720000 | K11: Push to PO
A12: 11 | B12: Naveena Group | C12: Textile | D12: A | E12: Active Opportunity | F12: UF 17 + HBWRO 8.5; BWRO 8; HBWRO 32 m³/hr proposals; group spans denim, apparel, steel | G12: UF + HBWRO | H12: GM Utilities; Group Engineering | I12: 52484000 | J12: 29532000 | K12: Bundle proposals; explore Naveena Steel water need
A13: 12 | B13: International Textile Ltd | C13: Textile | D13: A | E13: Active Opportunity | F13: SWRO 19/38 m³/hr, ETP revamp 50 m³/hr, reject RO 16 m³/hr | G13: SWRO, ETP revamp, reject RO | H13: GM Utilities; Director Technical | I13: 281748000 | K13: Prioritise SWRO 19 m³/hr firm offer
A14: 13 | B14: Liberty Mills | C14: Textile | D14: A | E14: Active Opportunity | F14: UF 100 m³/hr (PKR 52M) | G14: UF | H14: GM Utilities | I14: 51684000 | K14: Follow up on submitted proposal
A15: 14 | B15: Zaman Textile | C15: Textile | D15: A | E15: Active Opportunity | F15: Recycling UF 113 + BWRO 79 m³/hr (hot case) | G15: UF + BWRO recycling | H15: GM Utilities (Nadeem Naseer per visit plan) | K15: Technical follow-up
A16: 15 | B16: Digital Apparel | C16: Textile | D16: A | E16: Active Opportunity | F16: ETP extension 16→40 m³/hr UF + BWRO 28 m³/hr (PKR 23M, 50%) | G16: UF + BWRO, ETP extension | H16: Manager Utility (Faizan per visit plan) | J16: 22744000 | K16: Commercial negotiation
A17: 16 | B17: Jalal Sons | C17: Food & Beverage | D17: A | E17: Active Opportunity | F17: BWRO 12 m³/hr + storage (PKR 36M, 95%) | G17: BWRO | H17: Plant Manager; Procurement | J17: 35600000 | K17: Collect PO
A18: 17 | B18: Getz Pharma | C18: Pharmaceutical | D18: A | E18: Existing Customer | F18: UF 40 + BWRO 24; UF 59; containerized MBR ETP 200 m³/day; BWRO 14 — multiple units | G18: Pharma WTP (UF/RO), containerized MBR ETP | H18: Plant Director; Head of Engineering; Utilities Manager; QA/Validation Manager; Procurement Manager | I18: 143782000 | K18: Close Astola WTP; propose site-wide water master plan
A19: 18 | B19: Abbott Laboratories (Pakistan) | C19: Pharmaceutical | D19: A | E19: Active Opportunity | F19: UF 8 + RO 5.6; double-pass RO 4; UF 45 m³/hr | G19: UF, double-pass RO | H19: Plant Director; Head of Engineering; Utilities Manager; QA/Validation Manager; Procurement Manager | I19: 42476000 | K19: Follow up Landhi proposals
A20: 19 | B20: Martin Dow | C20: Pharmaceutical | D20: A | E20: Existing Customer | F20: UF 4.5 + BWRO 2.8 + pass-2 RO + EDI (PKR 27.5M); existing customer | G20: Purified water: UF, 2-pass RO, EDI | H20: Plant Director; Head of Engineering; Utilities Manager; QA/Validation Manager; Procurement Manager | J20: 27500000 | K20: Validation-package pitch
A21: 20 | B21: PharmEvo | C21: Pharmaceutical | D21: A | E21: Active Opportunity | F21: UF 4.5 + double-pass RO 2.6 + EDI 2.5 (PKR 32M) | G21: Purified water: UF, 2-pass RO, EDI | H21: Khalid Hassan (named in WR file); Head of Engineering | I21: 31820000 | K21: Follow up named contact
A22: 21 | B22: Otsuka Pakistan | C22: Pharmaceutical | D22: A | E22: Active Opportunity | F22: EDI 5.5 m³/hr + containerized IFAS ETP 5 m³/hr | G22: EDI, containerized IFAS ETP | H22: GM Engineering (Salman per visit plan) | I22: 10500000 | K22: Close EDI
A23: 22 | B23: Lucky Cement | C23: Cement | D23: A | E23: Active Opportunity | F23: RO recovery enhancement + 2nd pass RO + EDI; BWRO 15 m³/hr; group also has power, chemicals, auto | G23: RO/EDI boiler feed, BWRO | H23: GM Technical; Power Plant Manager | I23: 41592000 | K23: Use as entry to Lucky Group (LCI, Lucky Electric, Kia Lucky)
A24: 23 | B24: Pakistan Refinery Ltd (PRL) | C24: Oil & Gas | D24: A | E24: Active Opportunity | F24: WTP UF 67 + BWRO 50 m³/hr (PKR 63M); refinery upgrade programme | G24: UF + BWRO, process water | H24: Plant Manager; Chemistry/Water Treatment Manager; O&M Manager; Procurement Manager | I24: 63060000 | K24: Tender/technical follow-up
A25: 24 | B25: PARCO | C25: Oil & Gas | D25: A | E25: Existing Customer | F25: Two BWRO 2 m³/hr proposals; existing customer; very large refinery water system | G25: BWRO, refinery water & effluent | H25: Plant Manager; Chemistry/Water Treatment Manager; O&M Manager; Procurement Manager | I25: 56548610 | K25: Expand from small RO to utilities/effluent scope
A26: 25 | B26: Sindh Engro Coal Mining Co (SECMC) | C26: Mining & Minerals | D26: A | E26: Active Opportunity | F26: STP 2×25 m³/hr SBR (PKR 44M); Thar water-scarce site | G26: SBR STP, brackish RO, mine-water treatment | H26: Head of Projects; Utilities Manager | I26: 43654000 | K26: Follow up STP; open mine-water reuse discussion
A27: 26 | B27: Hilton Pharma | C27: Pharmaceutical | D27: A | E27: Existing Customer | F27: Bulk purified water 3 m³/hr + drinking water system proposals | G27: Purified water system | H27: Plant Director; Head of Engineering; Utilities Manager; QA/Validation Manager; Procurement Manager | I27: 34850000 | K27: Follow up submitted proposals
A28: 27 | B28: Genix Pharma | C28: Pharmaceutical | D28: A | E28: Active Opportunity | F28: Proposal PKR 36.5M (scope not described in WR file); existing customer per visit plan | G28: RO / purified water | H28: Plant Director; Head of Engineering; Utilities Manager; QA/Validation Manager; Procurement Manager | I28: 36480000 | K28: Fill missing scope in WR file; follow up
A29: 28 | B29: Willson Pharma | C29: Pharmaceutical | D29: A | E29: Active Opportunity | F29: BWRO 11.5 m³/hr (PKR 13.6M, 50%) | G29: BWRO | H29: Plant Director; Head of Engineering; Utilities Manager; QA/Validation Manager; Procurement Manager | J29: 13600000 | K29: Push to PO
A30: 29 | B30: Dynea Pakistan | C30: Chemicals & Petrochemical | D30: A | E30: Active Opportunity | F30: BWRO 6 m³/hr hot case; Senior Manager Mujtaba met Sep-26 | G30: BWRO + media filter | H30: Senior Manager (Mujtaba per visit plan) | K30: Follow up
A31: 30 | B31: Lucky Textile Mills (Unit 4) | C31: Textile | D31: A | E31: Existing Customer | F31: ETP revamp up to 200 m³/hr with primary treatment | G31: ETP revamp | H31: Director Technical; GM Utilities; ETP Manager; Sustainability/Compliance Manager; Procurement Manager | K31: Price the revamp; value missing in WR file
A32: 31 | B32: ATCO Group (ATCO Laboratories — confirm) | C32: Pharmaceutical | D32: A | E32: Active Opportunity | F32: ETP upgrade 250→500 m³/day IFAS + UF 10 / BWRO 6 m³/hr | G32: IFAS ETP, UF + BWRO | H32: Plant Director; Head of Engineering; Utilities Manager; QA/Validation Manager; Procurement Manager | I32: 43000000 | K32: Follow up (proposals dated Apr-2025 — re-qualify)
A33: 32 | B33: IFFCO (Pakistan) | C33: Food & Beverage | D33: A | E33: Active Opportunity | F33: HBWRO 45 m³/hr (PKR 75.8M) — proposal dated Sep-2024, re-qualify | G33: HBWRO | H33: Plant Manager; Engineering Manager; Utilities Manager; EHS Manager; Procurement Manager | I33: 75808000 | K33: Re-qualify: proposal is 2 years old
A34: 33 | B34: National Petro Carbon | C34: Chemicals & Petrochemical | D34: A | E34: Active Opportunity | F34: BWRO 23 m³/hr (PKR 36.6M) | G34: BWRO | H34: Plant Manager | I34: 36574000 | K34: Follow up
B35: TOTAL | I35: =SUM(I2:I34) -> 3696151810 | J35: =SUM(J2:J34) -> 852411200
B37: Values are as entered in WR's own Projects Pipeline / Expected-to-close sheets. Two real-estate STP proposals (HMR, The Court Group) are excluded because Real Estate is outside the current scope. Known data errors are listed in 'Data Issues'.

Sheet Master Companies
A1: WR ID | B1: Company | C1: Group | D1: Sector | E1: Sub-sector | F1: City | G1: Province | H1: List | I1: WR status | J1: Priority (new targets) | K1: Contact person | L1: Designation | M1: Phone | N1: Email | O1: Verification / basis | P1: Remarks
A2: WR-PK-0001 | B2: Agriauto Industries Ltd | D2: Automotive | E2: Auto parts | F2: Karachi | G2: Sindh | H2: New target | I2: Not yet contacted | J2: 2 | O2: Established operator — Nationally established manufacturer (PSX listed)
A3: WR-PK-0002 | B3: Al-Ghazi Tractors Ltd | C3: Al-Futtaim | D3: Automotive | E3: Tractors | F3: Dera Ghazi Khan | G3: Punjab | H3: New target | I3: Not yet contacted | J3: 2 | O3: Established operator — Established operator — listed or nationally known
A4: WR-PK-0003 | B4: Baluchistan Wheels Ltd | D4: Automotive | E4: Wheel rims | F4: Hub | G4: Balochistan | H4: New target | I4: Not yet contacted | J4: 2 | O4: Established operator — Nationally established manufacturer (PSX listed)
A5: WR-PK-0004 | B5: Ghandhara Industries Ltd (Isuzu) | C5: Bibojee Group | D5: Automotive | E5: Truck Assembly | F5: Karachi | G5: Sindh | H5: New target | I5: Not yet contacted | J5: 2 | O5: Established operator — Established operator — listed or nationally known
A6: WR-PK-0005 | B6: Hinopak Motors Ltd | C6: Hino / Toyota Tsusho | D6: Automotive | E6: Truck / Bus Assembly | F6: Karachi | G6: Sindh | H6: New target | I6: Not yet contacted | J6: 2 | O6: Established operator — Established operator — listed or nationally known
A7: WR-PK-0006 | B7: Honda Atlas Cars (Pakistan) Ltd | C7: Atlas Group | D7: Automotive | E7: OEM Assembly | F7: Lahore | G7: Punjab | H7: New target | I7: Not yet contacted | J7: 1 | O7: Established operator — Established operator — listed or nationally known | P7: Atlas group (Atlas Honda) already visited
A8: WR-PK-0007 | B8: Hyundai Nishat Motor (Pvt) Ltd | C8: Nishat Group | D8: Automotive | E8: OEM Assembly | F8: Faisalabad | G8: Punjab | H8: New target | I8: Not yet contacted | J8: 2 | O8: Established operator — Established operator — listed or nationally known | P8: Nishat group already a WR contact
A9: WR-PK-0008 | B9: Indus Motor Company Ltd (Toyota) | C9: House of Habib | D9: Automotive | E9: OEM Assembly (paint shop) | F9: Karachi (Port Qasim) | G9: Sindh | H9: New target | I9: Not yet contacted | J9: 1 | O9: Established operator — Established operator — listed or nationally known
A10: WR-PK-0009 | B10: Kia Lucky Motors Pakistan Ltd | C10: Lucky Group | D10: Automotive | E10: OEM Assembly | F10: Karachi (Bin Qasim) | G10: Sindh | H10: New target | I10: Not yet contacted | J10: 2 | O10: Established operator — Established operator — listed or nationally known | P10: Lucky group already a WR contact
A11: WR-PK-0010 | B11: Loads Ltd | D11: Automotive | E11: Auto parts (radiators / exhausts) | F11: Karachi | G11: Sindh | H11: New target | I11: Not yet contacted | J11: 2 | O11: Established operator — Nationally established manufacturer (PSX listed)
A12: WR-PK-0011 | B12: Master Changan Motors Ltd | C12: Master Group | D12: Automotive | E12: OEM Assembly | F12: Karachi | G12: Sindh | H12: New target | I12: Not yet contacted | J12: 2 | O12: Established operator — Established operator — listed or nationally known
A13: WR-PK-0012 | B13: Millat Tractors Ltd | C13: Millat | D13: Automotive | E13: Tractors | F13: Lahore | G13: Punjab | H13: New target | I13: Not yet contacted | J13: 2 | O13: Established operator — Established operator — listed or nationally known
A14: WR-PK-0013 | B14: Panther Tyres Ltd | D14: Automotive | E14: Tyres | F14: Sheikhupura | G14: Punjab | H14: New target | I14: Not yet contacted | J14: 2 | O14: Established operator — Established operator — listed or nationally known
A15: WR-PK-0014 | B15: Sazgar Engineering Works Ltd | C15: Sazgar | D15: Automotive | E15: OEM Assembly | F15: Lahore | G15: Punjab | H15: New target | I15: Not yet contacted | J15: 2 | O15: Established operator — Established operator — listed or nationally known
A16: WR-PK-0015 | B16: Yamaha Motor Pakistan (Pvt) Ltd | C16: Yamaha | D16: Automotive | E16: Motorcycles | F16: Karachi (Port Qasim) | G16: Sindh | H16: New target | I16: Not yet contacted | J16: 2 | O16: Established operator — Nationally established manufacturer
A17: WR-PK-0016 | B17: Atlas Battery Ltd | C17: Atlas Group | D17: Batteries | E17: Lead-Acid Batteries | F17: Karachi | G17: Sindh | H17: New target | I17: Not yet contacted | J17: 2 | O17: Established operator — Established operator — listed or nationally known | P17: Atlas group (Atlas Honda) already visited
A18: WR-PK-0017 | B18: Exide Pakistan Ltd | D18: Batteries | E18: Lead-Acid Batteries | F18: Karachi | G18: Sindh | H18: New target | I18: Not yet contacted | J18: 2 | O18: Established operator — Established operator — listed or nationally known
A19: WR-PK-0018 | B19: Attock Cement Pakistan - Hub Chowki, Lasbela | D19: Cement | E19: Cement | H19: WR existing list | I19: Not yet contacted | O19: WR internal list — field confirmation pending
A20: WR-PK-0019 | B20: D.G.Khan Cement Limited - Hub | C20: Nishat Group | D20: Cement | E20: Cement | F20: Dera Ghazi Khan / Khairpur / Hub | G20: Punjab | H20: WR existing list | I20: Not yet contacted | O20: WR internal list — field confirmation pending
A21: WR-PK-0020 | B21: Dada Bhai | D21: Cement | E21: Cement | H21: WR existing list | I21: Not yet contacted | O21: WR internal list — field confirmation pending
A22: WR-PK-0021 | B22: Dewan Cement Limited - Dhabeji | D22: Cement | E22: Cement | H22: WR existing list | I22: Closed / Not operating — Closed | O22: WR internal list — field confirmation pending | P22: Marked 'Closed' in WR file — confirm operating status
A23: WR-PK-0022 | B23: Lucky Cement Limited - Indus Highway, Karachi | D23: Cement | E23: Cement | H23: WR existing list | I23: In Contact | O23: WR internal list — field confirmation pending
A24: WR-PK-0023 | B24: Pioneer Cement | D24: Cement | E24: Cement | H24: WR existing list | I24: Not yet contacted | O24: WR internal list — field confirmation pending
A25: WR-PK-0024 | B25: Popular Cement Industries | D25: Cement | E25: Cement | H25: WR existing list | I25: Not yet contacted | O25: WR internal list — field confirmation pending
A26: WR-PK-0025 | B26: Power Cement Limited - Nooriabad, Dadu | D26: Cement | E26: Cement | H26: WR existing list | I26: In Contact | O26: WR internal list — field confirmation pending
A27: WR-PK-0026 | B27: Rohri Cement Private Limited | D27: Cement | E27: Cement | H27: WR existing list | I27: Not yet contacted | O27: WR internal list — field confirmation pending
A28: WR-PK-0027 | B28: Thatta Cement Limited - Thatta | D28: Cement | E28: Cement | H28: WR existing list | I28: In Contact | O28: WR internal list — field confirmation pending
A29: WR-PK-0028 | B29: Zeal Pak Cement | D29: Cement | E29: Cement | H29: WR existing list | I29: Closed / Not operating — Closed | O29: WR internal list — field confirmation pending
A30: WR-PK-0029 | B30: Asia Precious Mining Company | D30: Cement | E30: New cement plant | F30: Punjab — site to confirm | G30: Punjab | H30: New target | I30: Not yet contacted | J30: 1 | O30: Live project signal — One of 7 new cement plants approved, US$700M combined (Apr-2026)
A31: WR-PK-0030 | B31: Bestway Cement Ltd | C31: Bestway | D31: Cement | E31: Cement (multi-plant) | F31: Hattar / Chakwal / Kallar Kahar | G31: Punjab | H31: New target | I31: Not yet contacted | J31: 1 | O31: Established operator — Established operator — listed or nationally known
A32: WR-PK-0031 | B32: Buta Cement | D32: Cement | E32: New cement plant | F32: Punjab — site to confirm | G32: Punjab | H32: New target | I32: Not yet contacted | J32: 1 | O32: Live project signal — One of 7 new cement plants approved, US$700M combined (Apr-2026)
A33: WR-PK-0032 | B33: Cherat Cement Co Ltd | C33: Ghulam Faruque Group | D33: Cement | E33: Cement | F33: Nowshera | G33: KPK | H33: New target | I33: Not yet contacted | J33: 2 | O33: Established operator — Established operator — listed or nationally known
A34: WR-PK-0033 | B34: Dandot Cement Company Ltd | D34: Cement | E34: Cement (new project) | F34: Dandot (Jhelum) | G34: Punjab | H34: New target | I34: Not yet contacted | J34: 1 | O34: Live project signal — One of 7 new cement plants approved, US$700M combined (Apr-2026)
A35: WR-PK-0034 | B35: Fauji Cement Company Ltd | C35: Fauji Foundation | D35: Cement | E35: Cement (multi-plant) | F35: Jhang Bahtar / Nizampur / D.G. Khan | G35: Punjab | H35: New target | I35: Not yet contacted | J35: 1 | O35: Established operator — Established operator — listed or nationally known
A36: WR-PK-0035 | B36: Fecto Cement Ltd | C36: Fecto Group | D36: Cement | E36: Cement | F36: Sangjani | G36: Punjab | H36: New target | I36: Not yet contacted | J36: 2 | O36: Established operator — Established operator — listed or nationally known
A37: WR-PK-0036 | B37: Flying Cement Co Ltd | C37: Flying Group | D37: Cement | E37: Cement | F37: Khushab | G37: Punjab | H37: New target | I37: Not yet contacted | J37: 2 | O37: Established operator — Established operator — listed or nationally known
A38: WR-PK-0037 | B38: Gharibwal Cement Ltd | D38: Cement | E38: Cement | F38: Jhelum | G38: Punjab | H38: New target | I38: Not yet contacted | J38: 2 | O38: Established operator — Established operator — listed or nationally known
A39: WR-PK-0038 | B39: Kohat Cement Co Ltd | D39: Cement | E39: Cement | F39: Kohat | G39: KPK | H39: New target | I39: Not yet contacted | J39: 2 | O39: Established operator — Established operator — listed or nationally known
A40: WR-PK-0039 | B40: Lucky Cement Ltd — Pezu Plant | C40: Lucky Group | D40: Cement | E40: Cement | F40: Pezu (Lakki Marwat) | G40: KPK | H40: New target | I40: Not yet contacted | J40: 2 | O40: Established operator — Established operator — listed or nationally known | P40: Lucky Cement Karachi already a WR contact
...

Sheet Sector Taxonomy
A1: Code | B1: Sector | C1: Sub-sectors | D1: Water / wastewater need | E1: WR solutions | F1: Typical decision-makers | G1: Priority (1 = highest)
A2: TX | B2: Textile | C2: Denim; Knitwear & Apparel; Woven & Weaving; Towel & Terry; Home Textile; Dyeing & Printing; Spinning; Composite | D2: High-COD, coloured effluent; reuse targets; ZDHC / brand compliance | E2: ETP (MBR/MBBR/IFAS), UF+BWRO recycling, HBWRO, ZLD | F2: GM Utilities; ETP Manager; Director Technical; Sustainability Manager | G2: 1
A3: PH | B3: Pharmaceutical & Healthcare | C3: Sterile/Injectables; Orals/Solids; API/Bulk; Consumer Healthcare; Hospitals; Renal/dialysis centres | D3: USP purified water, WFI feed, validation; pharma effluent; dialysis-grade water, CSSD, hospital STP | E3: 2-pass RO, EDI, UF, containerized MBR/IFAS ETP; dialysis RO; STP | F3: Head of Engineering; Utilities; QA/Validation; Director Facilities; Biomedical | G3: 1
A4: FB | B4: Food & Beverage | C4: Dairy; Carbonated drinks; Juices; Bottled water; Brewery; Confectionery; Poultry; Edible oil; Starch; Rice | D4: Process & bottle-wash water; high-BOD effluent; CIP | E4: RO/UF process water, anaerobic+aerobic ETP, reuse | F4: Plant Manager; Utilities; EHS | G4: 1
A5: SG | B5: Sugar & Distillery | C5: Sugar; Ethanol distillery; Co-generation | D5: Boiler feed for co-gen; spent wash; seasonal effluent | E5: DM/RO boiler feed, condensate polishing, distillery ETP/ZLD | F5: GM Technical; Co-gen Manager | G5: 1
A6: CH | B6: Chemicals & Petrochemical | C6: Chlor-alkali; Soda ash; Peroxide; Dyes; Specialty; Industrial gases; Paints | D6: Demin water, brine, hazardous effluent | E6: DM/RO, brine RO, ETP, ZLD | F6: Plant Manager; EHS; Engineering | G6: 1
A7: OG | B7: Oil & Gas | C7: Refinery; Upstream E&P; Oil marketing depots; Gas utility | D7: Process water, produced water, oily effluent | E7: Refinery ETP, BWRO/SWRO, produced-water treatment | F7: Utilities/Process Manager; Procurement | G7: 1
A8: FT | B8: Fertilizer | C8: Urea/Ammonia; CAN/NP/DAP | D8: Very high cooling & boiler water; blowdown | E8: Blowdown recycling, DM/RO, ZLD | F8: Utilities Manager; Plant Manager | G8: 1
A9: PW | B9: Power | C9: Coal; RLNG/combined cycle; Oil; Thar coal; Nuclear | D9: Boiler make-up, cooling, FGD effluent, ZLD | E9: SWRO/BWRO, DM, mixed-bed, ETP, ZLD | F9: Chemistry Manager; O&M Manager | G9: 1
A10: CM | B10: Cement | C10: Cement with captive power / WHR | D10: Boiler feed, cooling | E10: Boiler-feed RO/DM, softening | F10: GM Technical; Power Plant Manager | G10: 2
A11: ST | B11: Steel & Metals | C11: Long steel; Flat/galvanizing; Pipes; Non-ferrous | D11: Cooling & scale water; pickling acid | E11: Cooling water treatment, acid effluent ETP, RO reuse | F11: Plant Head; Utilities | G11: 1
A12: MN | B12: Mining & Minerals | C12: Coal (Thar); Copper-gold; Lead-zinc | D12: Mine-water, brackish groundwater, camp STP | E12: Brackish RO, mine-water treatment, STP | F12: Head of Projects; Utilities | G12: 2
... A20: EP | B20: EPC / Consultant (Partner) | C20: EPC contractors; Consultants; MEP | D20: Water packages inside larger projects | E20: Subcontract / specification | F20: BD Head; Procurement | G20: Partner

Sheet Data Issues
A1: File / sheet | B1: Location | C1: Company | D1: Issue | E1: Action
A2: Industries List / Textile | B2: Row 11 | C2: National Refinery Limited | D2: Not a textile company — listed under Textile | E2: Re-classified to Oil & Gas
A3: Industries List / Textile | B3: Row 18 | C3: International Steels Limited | D3: Not a textile company — listed under Textile | E3: Re-classified to Steel & Metals
A4: Industries List / Textile | B4: Row 26 | C4: Shafi Glucochem (Pvt) Limited | D4: Not a textile company — listed under Textile | E4: Re-classified to Food & Beverage
A5: Industries List / Textile | B5: Row 39 | C5: International Industries Limited | D5: Not a textile company — listed under Textile | E5: Re-classified to Steel & Metals
A6: Industries List / Textile | B6: Row 44 | C6: United Energy Pakistan Limited | D6: Not a textile company — listed under Textile | E6: Re-classified to Oil & Gas
A7: Industries List / Petrochemical | B7: Row 5 | C7: Byco Petroleum Pakistan Ltd | D7: Columns shifted: 'Syed Shehensha Naqvi' sits in Sales Manager and phone '03332358906' sits in Contact Person | E7: Moved to Contact / Phone in master
A8: Industries List / Oil & Gas | B8: Row 2 | C8: United Energy Pakistan limited | D8: Columns shifted: 'Waqas' sits in Sales Manager and phone '03018292379' sits in Contact Person | E8: Moved to Contact / Phone in master
A9: Industries List / Towel | B9: — | C9: Afroze Textile Industries (Pvt) Ltd. | D9: Duplicate of 'Afroze Textiles Industries (Private) Limited' (Textile) | E9: Merged into one record
A10: Industries List / Towel | B10: — | C10: Al Rahim Textile Industries | D10: Duplicate of 'Al Rahim Textile Industries Limited' (Textile) | E10: Merged into one record
A11: Industries List / Towel | B11: — | C11: Al-Karam Textile | D11: Duplicate of 'Al-Karam Textile Mills (Private) Limited' (Textile) | E11: Merged into one record
A12: Industries List / Towel | B12: — | C12: Al-Karam Towel Industries (Pvt) Ltd | D12: Duplicate of 'Al-Karam Towel Industries' (Textile) | E12: Merged into one record
... A110: Visit Plan / Oct 05-10 | B110: — | C110: Tufail Chemicals | D110: Same group appears in the Punjab EPD register as Tufail Starchem Industries (new chemicals unit, Kasur) | E110: Treat as existing WR contact; follow up the new unit

Sheet Review Findings
A1: Severity | B1: Area | C1: Weak point found | D1: Fix | E1: Status
A2: Critical | B2: Process | C2: No activity log for emails, calls and company registrations — Weekly Dashboard counts them but the system design only logged visits | D2: Added 'Activity' record (Visit / Call / Email / Registration / Proposal follow-up). Every dashboard KPI is a count of activities — nothing typed by hand | E2: Fixed in design
A3: Critical | B3: Process | C3: Targets had no owner — rep could type his own target | D3: Manager sets weekly/monthly targets per rep; rep sees target vs actual | E3: Fixed in design
A4: Critical | B4: Data | C4: Pipeline figures in WR file contain errors (softening plant ~100× overvalued; Feroze Hub RO double-counted; text in amount field) | D4: Listed in 'Data Issues' sheet; must be corrected before import, otherwise CEO cockpit shows wrong pipeline | E4: Needs WR correction
A5: Critical | B5: Accuracy | C5: My earlier chat figure for 'Expected to close' (~1,159M) was wrong | D5: Correct: PKR 852.4M across 10 priced deals; probability-weighted PKR 584.6M | E5: Corrected
A6: Critical | B6: Accuracy | C6: Earlier chat company lists contained unverifiable or wrong names (e.g. 'Shezan Pakistan Glass', 'Lotte CNG', laundry names) | D6: All removed — see 'Removed Names' sheet. Master now holds only WR's own list + known operating companies | E6: Corrected
A7: Critical | B7: Hosting | C7: Unknown whether waterregime.com hosting (Hostinger) runs Python apps | D7: Check hPanel for Python/Node support or VPS plan before Day 11. App will be built MySQL-compatible. Do NOT move nameservers — website and email must stay untouched | E7: Open — check hPanel
A8: High | B8: Working model | C8: I said deliverables would be ready 'by tomorrow morning' — I only work while a session is open; nothing progresses in the background | D8: Each build step is done inside a working session with you; code stored in a repo you own so nothing is lost between sessions | E8: Corrected
A9: High | B9: Email | C9: Earlier plan used Gmail SMTP; WR memory notes the Hostinger mailbox is incompatible with Gmail/MS365 connectors | D9: Portal sends notifications through Hostinger SMTP (noreply@waterregime.com) — standard SMTP works even where connectors do not. Weekly digest via hosting cron | E9: Fixed in design
A10: High | B10: Assignment | C10: Assignment by Region+Sector breaks when one group has plants in several regions (Nishat, Lucky, Fatima) | D10: Owner is set at plant/unit level; group view rolls up for CEO | E10: Fixed in design
A11: High | B11: Visit Plan | C11: Existing plan has 'Amended Visit Plan' column — plan-vs-actual was missing in portal design | D11: Planned visit can be marked Done / Replaced (with replacement company) / Cancelled (reason) | E11: Fixed in design
